Traceback (most recent call last):
  File "run/wsgi.py", line 6, in <module>
    omnibus.run(host='0.0.0.0', port=9000)
  File "/usr/local/lib/python3.5/dist-packages/flask/app.py", line 841, in run
    run_simple(host, port, self, **options)
  File "/usr/local/lib/python3.5/dist-packages/werkzeug/serving.py", line 799, in run_simple
    inner()
  File "/usr/local/lib/python3.5/dist-packages/werkzeug/serving.py", line 759, in inner
    fd=fd)
  File "/usr/local/lib/python3.5/dist-packages/werkzeug/serving.py", line 651, in make_server
    passthrough_errors, ssl_context, fd=fd)
  File "/usr/local/lib/python3.5/dist-packages/werkzeug/serving.py", line 562, in __init__
    HTTPServer.__init__(self, (host, int(port)), handler)
  File "/usr/lib/python3.5/socketserver.py", line 440, in __init__
    self.server_bind()
  File "/usr/lib/python3.5/http/server.py", line 138, in server_bind
    socketserver.TCPServer.server_bind(self)
  File "/usr/lib/python3.5/socketserver.py", line 454, in server_bind
    self.socket.bind(self.server_address)
OSError: [Errno 98] Address already in use
 * Running on http://0.0.0.0:9000/ (Press CTRL+C to quit)
[2018-04-12 20:07:45,694] ERROR in app: Exception on /edchain/courses/ [POST]
Traceback (most recent call last):
  File "/usr/local/lib/python3.5/dist-packages/flask/app.py", line 1982, in wsgi_app
    response = self.full_dispatch_request()
  File "/usr/local/lib/python3.5/dist-packages/flask/app.py", line 1614, in full_dispatch_request
    rv = self.handle_user_exception(e)
  File "/usr/local/lib/python3.5/dist-packages/flask/app.py", line 1517, in handle_user_exception
    reraise(exc_type, exc_value, tb)
  File "/usr/local/lib/python3.5/dist-packages/flask/_compat.py", line 33, in reraise
    raise value
  File "/usr/local/lib/python3.5/dist-packages/flask/app.py", line 1612, in full_dispatch_request
    rv = self.dispatch_request()
  File "/usr/local/lib/python3.5/dist-packages/flask/app.py", line 1598, in dispatch_request
    return self.view_functions[rule.endpoint](**req.view_args)
  File "/root/ae9000/run/core/endpoints/courses.py", line 15, in get_courses
    with open('datastore/searchspace6.json', 'r') as file:
FileNotFoundError: [Errno 2] No such file or directory: 'datastore/searchspace6.json'
206.252.214.165 - - [12/Apr/2018 20:07:45] "POST /edchain/courses/ HTTP/1.1" 500 -
Traceback (most recent call last):
  File "run/wsgi.py", line 6, in <module>
    omnibus.run(host='0.0.0.0', port=9000)
  File "/usr/local/lib/python3.5/dist-packages/flask/app.py", line 841, in run
    run_simple(host, port, self, **options)
  File "/usr/local/lib/python3.5/dist-packages/werkzeug/serving.py", line 799, in run_simple
    inner()
  File "/usr/local/lib/python3.5/dist-packages/werkzeug/serving.py", line 759, in inner
    fd=fd)
  File "/usr/local/lib/python3.5/dist-packages/werkzeug/serving.py", line 651, in make_server
    passthrough_errors, ssl_context, fd=fd)
  File "/usr/local/lib/python3.5/dist-packages/werkzeug/serving.py", line 562, in __init__
    HTTPServer.__init__(self, (host, int(port)), handler)
  File "/usr/lib/python3.5/socketserver.py", line 440, in __init__
    self.server_bind()
  File "/usr/lib/python3.5/http/server.py", line 138, in server_bind
    socketserver.TCPServer.server_bind(self)
  File "/usr/lib/python3.5/socketserver.py", line 454, in server_bind
    self.socket.bind(self.server_address)
OSError: [Errno 98] Address already in use
 * Running on http://0.0.0.0:9000/ (Press CTRL+C to quit)
[2018-04-12 20:09:54,665] ERROR in app: Exception on /edchain/courses/ [POST]
Traceback (most recent call last):
  File "/usr/local/lib/python3.5/dist-packages/flask/app.py", line 1982, in wsgi_app
    response = self.full_dispatch_request()
  File "/usr/local/lib/python3.5/dist-packages/flask/app.py", line 1614, in full_dispatch_request
    rv = self.handle_user_exception(e)
  File "/usr/local/lib/python3.5/dist-packages/flask/app.py", line 1517, in handle_user_exception
    reraise(exc_type, exc_value, tb)
  File "/usr/local/lib/python3.5/dist-packages/flask/_compat.py", line 33, in reraise
    raise value
  File "/usr/local/lib/python3.5/dist-packages/flask/app.py", line 1612, in full_dispatch_request
    rv = self.dispatch_request()
  File "/usr/local/lib/python3.5/dist-packages/flask/app.py", line 1598, in dispatch_request
    return self.view_functions[rule.endpoint](**req.view_args)
  File "/root/ae9000/run/core/endpoints/courses.py", line 15, in get_courses
    with open('core/datastore/searchspace6.json', 'r') as file:
FileNotFoundError: [Errno 2] No such file or directory: 'core/datastore/searchspace6.json'
206.252.214.165 - - [12/Apr/2018 20:09:54] "POST /edchain/courses/ HTTP/1.1" 500 -
Traceback (most recent call last):
  File "run/wsgi.py", line 6, in <module>
    omnibus.run(host='0.0.0.0', port=9000)
  File "/usr/local/lib/python3.5/dist-packages/flask/app.py", line 841, in run
    run_simple(host, port, self, **options)
  File "/usr/local/lib/python3.5/dist-packages/werkzeug/serving.py", line 799, in run_simple
    inner()
  File "/usr/local/lib/python3.5/dist-packages/werkzeug/serving.py", line 759, in inner
    fd=fd)
  File "/usr/local/lib/python3.5/dist-packages/werkzeug/serving.py", line 651, in make_server
    passthrough_errors, ssl_context, fd=fd)
  File "/usr/local/lib/python3.5/dist-packages/werkzeug/serving.py", line 562, in __init__
    HTTPServer.__init__(self, (host, int(port)), handler)
  File "/usr/lib/python3.5/socketserver.py", line 440, in __init__
    self.server_bind()
  File "/usr/lib/python3.5/http/server.py", line 138, in server_bind
    socketserver.TCPServer.server_bind(self)
  File "/usr/lib/python3.5/socketserver.py", line 454, in server_bind
    self.socket.bind(self.server_address)
OSError: [Errno 98] Address already in use
104.11.163.73 - - [12/Apr/2018 21:10:04] "GET / HTTP/1.1" 200 -
104.11.163.73 - - [12/Apr/2018 21:10:04] "GET / HTTP/1.1" 200 -
104.11.163.73 - - [12/Apr/2018 21:10:05] "GET /favicon.ico HTTP/1.1" 404 -
104.11.163.73 - - [12/Apr/2018 21:10:15] "GET / HTTP/1.1" 200 -
104.11.163.73 - - [12/Apr/2018 21:10:15] "GET / HTTP/1.1" 200 -
104.11.163.73 - - [12/Apr/2018 21:10:45] "GET / HTTP/1.1" 200 -
104.11.163.73 - - [12/Apr/2018 21:10:46] "GET / HTTP/1.1" 200 -
104.11.163.73 - - [12/Apr/2018 21:10:48] "GET / HTTP/1.1" 200 -
104.11.163.73 - - [12/Apr/2018 21:19:11] "GET / HTTP/1.1" 200 -
[2018-04-12 21:27:51,188] ERROR in app: Exception on /edchain/courses/ [GET]
Traceback (most recent call last):
  File "/usr/local/lib/python3.5/dist-packages/flask/app.py", line 1982, in wsgi_app
    response = self.full_dispatch_request()
  File "/usr/local/lib/python3.5/dist-packages/flask/app.py", line 1614, in full_dispatch_request
    rv = self.handle_user_exception(e)
  File "/usr/local/lib/python3.5/dist-packages/flask/app.py", line 1517, in handle_user_exception
    reraise(exc_type, exc_value, tb)
  File "/usr/local/lib/python3.5/dist-packages/flask/_compat.py", line 33, in reraise
    raise value
  File "/usr/local/lib/python3.5/dist-packages/flask/app.py", line 1612, in full_dispatch_request
    rv = self.dispatch_request()
  File "/usr/local/lib/python3.5/dist-packages/flask/app.py", line 1598, in dispatch_request
    return self.view_functions[rule.endpoint](**req.view_args)
  File "/root/ae9000/run/core/endpoints/courses.py", line 15, in get_courses
    with open('core/datastore/searchspace6.json', 'r') as file:
FileNotFoundError: [Errno 2] No such file or directory: 'core/datastore/searchspace6.json'
104.11.163.73 - - [12/Apr/2018 21:27:51] "GET /edchain/courses/ HTTP/1.1" 500 -
[2018-04-12 21:29:40,986] ERROR in app: Exception on /edchain/courses/ [GET]
Traceback (most recent call last):
  File "/usr/local/lib/python3.5/dist-packages/flask/app.py", line 1982, in wsgi_app
    response = self.full_dispatch_request()
  File "/usr/local/lib/python3.5/dist-packages/flask/app.py", line 1614, in full_dispatch_request
    rv = self.handle_user_exception(e)
  File "/usr/local/lib/python3.5/dist-packages/flask/app.py", line 1517, in handle_user_exception
    reraise(exc_type, exc_value, tb)
  File "/usr/local/lib/python3.5/dist-packages/flask/_compat.py", line 33, in reraise
    raise value
  File "/usr/local/lib/python3.5/dist-packages/flask/app.py", line 1612, in full_dispatch_request
    rv = self.dispatch_request()
  File "/usr/local/lib/python3.5/dist-packages/flask/app.py", line 1598, in dispatch_request
    return self.view_functions[rule.endpoint](**req.view_args)
  File "/root/ae9000/run/core/endpoints/courses.py", line 15, in get_courses
    with open('core/datastore/searchspace6.json', 'r') as file:
FileNotFoundError: [Errno 2] No such file or directory: 'core/datastore/searchspace6.json'
104.11.163.73 - - [12/Apr/2018 21:29:40] "GET /edchain/courses/ HTTP/1.1" 500 -
[2018-04-12 21:29:52,041] ERROR in app: Exception on /edchain/courses/ [POST]
Traceback (most recent call last):
  File "/usr/local/lib/python3.5/dist-packages/flask/app.py", line 1982, in wsgi_app
    response = self.full_dispatch_request()
  File "/usr/local/lib/python3.5/dist-packages/flask/app.py", line 1614, in full_dispatch_request
    rv = self.handle_user_exception(e)
  File "/usr/local/lib/python3.5/dist-packages/flask/app.py", line 1517, in handle_user_exception
    reraise(exc_type, exc_value, tb)
  File "/usr/local/lib/python3.5/dist-packages/flask/_compat.py", line 33, in reraise
    raise value
  File "/usr/local/lib/python3.5/dist-packages/flask/app.py", line 1612, in full_dispatch_request
    rv = self.dispatch_request()
  File "/usr/local/lib/python3.5/dist-packages/flask/app.py", line 1598, in dispatch_request
    return self.view_functions[rule.endpoint](**req.view_args)
  File "/root/ae9000/run/core/endpoints/courses.py", line 15, in get_courses
    with open('core/datastore/searchspace6.json', 'r') as file:
FileNotFoundError: [Errno 2] No such file or directory: 'core/datastore/searchspace6.json'
104.11.163.73 - - [12/Apr/2018 21:29:52] "POST /edchain/courses/ HTTP/1.1" 500 -
104.11.163.73 - - [12/Apr/2018 21:32:07] "GET / HTTP/1.1" 200 -
104.11.163.73 - - [12/Apr/2018 21:32:11] "GET / HTTP/1.1" 200 -
104.11.163.73 - - [12/Apr/2018 21:37:05] "GET / HTTP/1.1" 200 -
[2018-04-12 21:42:39,869] ERROR in app: Exception on /edchain/courses/ [POST]
Traceback (most recent call last):
  File "/usr/local/lib/python3.5/dist-packages/flask/app.py", line 1982, in wsgi_app
    response = self.full_dispatch_request()
  File "/usr/local/lib/python3.5/dist-packages/flask/app.py", line 1614, in full_dispatch_request
    rv = self.handle_user_exception(e)
  File "/usr/local/lib/python3.5/dist-packages/flask/app.py", line 1517, in handle_user_exception
    reraise(exc_type, exc_value, tb)
  File "/usr/local/lib/python3.5/dist-packages/flask/_compat.py", line 33, in reraise
    raise value
  File "/usr/local/lib/python3.5/dist-packages/flask/app.py", line 1612, in full_dispatch_request
    rv = self.dispatch_request()
  File "/usr/local/lib/python3.5/dist-packages/flask/app.py", line 1598, in dispatch_request
    return self.view_functions[rule.endpoint](**req.view_args)
  File "/root/ae9000/run/core/endpoints/courses.py", line 15, in get_courses
    with open('core/datastore/searchspace6.json', 'r') as file:
FileNotFoundError: [Errno 2] No such file or directory: 'core/datastore/searchspace6.json'
206.252.214.165 - - [12/Apr/2018 21:42:39] "POST /edchain/courses/ HTTP/1.1" 500 -
104.11.163.73 - - [12/Apr/2018 21:43:33] "GET / HTTP/1.1" 200 -
104.11.163.73 - - [12/Apr/2018 21:44:04] "GET / HTTP/1.1" 200 -
104.11.163.73 - - [12/Apr/2018 21:47:39] "GET / HTTP/1.1" 200 -
[2018-04-12 21:47:39,229] ERROR in app: Exception on /edchain/courses/ [POST]
Traceback (most recent call last):
  File "/usr/local/lib/python3.5/dist-packages/flask/app.py", line 1982, in wsgi_app
    response = self.full_dispatch_request()
  File "/usr/local/lib/python3.5/dist-packages/flask/app.py", line 1614, in full_dispatch_request
    rv = self.handle_user_exception(e)
  File "/usr/local/lib/python3.5/dist-packages/flask/app.py", line 1517, in handle_user_exception
    reraise(exc_type, exc_value, tb)
  File "/usr/local/lib/python3.5/dist-packages/flask/_compat.py", line 33, in reraise
    raise value
  File "/usr/local/lib/python3.5/dist-packages/flask/app.py", line 1612, in full_dispatch_request
    rv = self.dispatch_request()
  File "/usr/local/lib/python3.5/dist-packages/flask/app.py", line 1598, in dispatch_request
    return self.view_functions[rule.endpoint](**req.view_args)
  File "/root/ae9000/run/core/endpoints/courses.py", line 15, in get_courses
    with open('datastore/searchspace6.json', 'r') as file:
FileNotFoundError: [Errno 2] No such file or directory: 'core/datastore/searchspace6.json'
206.252.214.165 - - [12/Apr/2018 21:47:39] "POST /edchain/courses/ HTTP/1.1" 500 -
104.11.163.73 - - [12/Apr/2018 21:47:39] "GET / HTTP/1.1" 200 -
104.11.163.73 - - [12/Apr/2018 21:47:41] "GET / HTTP/1.1" 200 -
104.11.163.73 - - [12/Apr/2018 21:47:43] "GET / HTTP/1.1" 200 -
